
====================================
Iteration: 1
====================================
Traceback (most recent call last):
  File "C:\Users\manir\Desktop\intro to ML\Proj\JailbreakingLLMs\language_models.py", line 198, in generate
    response = openai.ChatCompletion.create(
               ^^^^^^^^^^^^^^^^^^^^^^^^^^^^^
  File "C:\Users\manir\AppData\Roaming\Python\Python312\site-packages\openai\lib\_old_api.py", line 39, in __call__
    raise APIRemovedInV1(symbol=self._symbol)
openai.lib._old_api.APIRemovedInV1:

You tried to access openai.ChatCompletion, but this is no longer supported in openai>=1.0.0 - see the README at https://github.com/openai/openai-python for the API.

You can run `openai migrate` to automatically upgrade your codebase to use the 1.0.0 interface.

Alternatively, you can pin your installation to the old version, e.g. `pip install openai==0.28`

A detailed migration guide is available here: https://github.com/openai/openai-python/discussions/742


During handling of the above exception, another exception occurred:

Traceback (most recent call last):
  File "C:\Users\manir\Desktop\intro to ML\Proj\JailbreakingLLMs\main.py", line 190, in <module>
    main(args)
  File "C:\Users\manir\Desktop\intro to ML\Proj\JailbreakingLLMs\main.py", line 38, in main
    extracted_attack_list = attackLM.get_attack(convs_list, processed_response_list)
                            ^^^^^^^^^^^^^^^^^^^^^^^^^^^^^^^^^^^^^^^^^^^^^^^^^^^^^^^^
  File "C:\Users\manir\Desktop\intro to ML\Proj\JailbreakingLLMs\conversers.py", line 93, in get_attack
    outputs_list = self.model.batched_generate(full_prompts_subset,
                   ^^^^^^^^^^^^^^^^^^^^^^^^^^^^^^^^^^^^^^^^^^^^^^^^
  File "C:\Users\manir\Desktop\intro to ML\Proj\JailbreakingLLMs\language_models.py", line 220, in batched_generate
    return [self.generate(conv, max_n_tokens, temperature, top_p) for conv in convs_list]
            ^^^^^^^^^^^^^^^^^^^^^^^^^^^^^^^^^^^^^^^^^^^^^^^^^^^^^
  File "C:\Users\manir\Desktop\intro to ML\Proj\JailbreakingLLMs\language_models.py", line 208, in generate
    except openai.error.OpenAIError as e:
           ^^^^^^^^^^^^
AttributeError: module 'openai' has no attribute 'error'
