
====================================
Iteration: 1
====================================
Traceback (most recent call last):
  File "C:\Users\manir\Desktop\intro to ML\Proj\JailbreakingLLMs\language_models.py", line 199, in generate
    response = openai.chat.completions.create(
               ^^^^^^^^^^^^^^^^^^^^^^^^^^^^^^^
  File "C:\Users\manir\AppData\Roaming\Python\Python312\site-packages\openai\_utils\_utils.py", line 275, in wrapper
    return func(*args, **kwargs)
           ^^^^^^^^^^^^^^^^^^^^^
TypeError: Completions.create() got an unexpected keyword argument 'request_timeout'

During handling of the above exception, another exception occurred:

Traceback (most recent call last):
  File "C:\Users\manir\Desktop\intro to ML\Proj\JailbreakingLLMs\main.py", line 190, in <module>
    main(args)
  File "C:\Users\manir\Desktop\intro to ML\Proj\JailbreakingLLMs\main.py", line 38, in main
    extracted_attack_list = attackLM.get_attack(convs_list, processed_response_list)
                            ^^^^^^^^^^^^^^^^^^^^^^^^^^^^^^^^^^^^^^^^^^^^^^^^^^^^^^^^
  File "C:\Users\manir\Desktop\intro to ML\Proj\JailbreakingLLMs\conversers.py", line 93, in get_attack
    outputs_list = self.model.batched_generate(full_prompts_subset,
                   ^^^^^^^^^^^^^^^^^^^^^^^^^^^^^^^^^^^^^^^^^^^^^^^^
  File "C:\Users\manir\Desktop\intro to ML\Proj\JailbreakingLLMs\language_models.py", line 221, in batched_generate
    return [self.generate(conv, max_n_tokens, temperature, top_p) for conv in convs_list]
            ^^^^^^^^^^^^^^^^^^^^^^^^^^^^^^^^^^^^^^^^^^^^^^^^^^^^^
  File "C:\Users\manir\Desktop\intro to ML\Proj\JailbreakingLLMs\language_models.py", line 209, in generate
    except openai.error.OpenAIError as e:
           ^^^^^^^^^^^^
AttributeError: module 'openai' has no attribute 'error'
